Traceback (most recent call last):
  File "C:\Users\skorczewskit\Anaconda3\lib\site-packages\jupyter_cache\executors\utils.py", line 58, in single_nb_execution
    executenb(
  File "C:\Users\skorczewskit\Anaconda3\lib\site-packages\nbclient\client.py", line 1204, in execute
    return NotebookClient(nb=nb, resources=resources, km=km, **kwargs).execute()
  File "C:\Users\skorczewskit\Anaconda3\lib\site-packages\nbclient\util.py", line 84, in wrapped
    return just_run(coro(*args, **kwargs))
  File "C:\Users\skorczewskit\Anaconda3\lib\site-packages\nbclient\util.py", line 62, in just_run
    return loop.run_until_complete(coro)
  File "C:\Users\skorczewskit\Anaconda3\lib\asyncio\base_events.py", line 647, in run_until_complete
    return future.result()
  File "C:\Users\skorczewskit\Anaconda3\lib\site-packages\nbclient\client.py", line 663, in async_execute
    await self.async_execute_cell(
  File "C:\Users\skorczewskit\Anaconda3\lib\site-packages\nbclient\client.py", line 965, in async_execute_cell
    await self._check_raise_for_error(cell, cell_index, exec_reply)
  File "C:\Users\skorczewskit\Anaconda3\lib\site-packages\nbclient\client.py", line 862, in _check_raise_for_error
    raise CellExecutionError.from_cell_and_msg(cell, exec_reply_content)
nbclient.exceptions.CellExecutionError: An error occurred while executing the following cell:
------------------
r = np.linalg.solve(M2,B2)
------------------

[1;31m---------------------------------------------------------------------------[0m
[1;31mLinAlgError[0m                               Traceback (most recent call last)
Input [1;32mIn [5][0m, in [0;36m<cell line: 1>[1;34m()[0m
[1;32m----> 1[0m r [38;5;241m=[39m [43mnp[49m[38;5;241;43m.[39;49m[43mlinalg[49m[38;5;241;43m.[39;49m[43msolve[49m[43m([49m[43mM2[49m[43m,[49m[43mB2[49m[43m)[49m

File [1;32m~\Anaconda3\lib\site-packages\numpy\linalg\linalg.py:409[0m, in [0;36msolve[1;34m(a, b)[0m
[0;32m    407[0m signature [38;5;241m=[39m [38;5;124m'[39m[38;5;124mDD->D[39m[38;5;124m'[39m [38;5;28;01mif[39;00m isComplexType(t) [38;5;28;01melse[39;00m [38;5;124m'[39m[38;5;124mdd->d[39m[38;5;124m'[39m
[0;32m    408[0m extobj [38;5;241m=[39m get_linalg_error_extobj(_raise_linalgerror_singular)
[1;32m--> 409[0m r [38;5;241m=[39m [43mgufunc[49m[43m([49m[43ma[49m[43m,[49m[43m [49m[43mb[49m[43m,[49m[43m [49m[43msignature[49m[38;5;241;43m=[39;49m[43msignature[49m[43m,[49m[43m [49m[43mextobj[49m[38;5;241;43m=[39;49m[43mextobj[49m[43m)[49m
[0;32m    411[0m [38;5;28;01mreturn[39;00m wrap(r[38;5;241m.[39mastype(result_t, copy[38;5;241m=[39m[38;5;28;01mFalse[39;00m))

File [1;32m~\Anaconda3\lib\site-packages\numpy\linalg\linalg.py:112[0m, in [0;36m_raise_linalgerror_singular[1;34m(err, flag)[0m
[0;32m    111[0m [38;5;28;01mdef[39;00m [38;5;21m_raise_linalgerror_singular[39m(err, flag):
[1;32m--> 112[0m     [38;5;28;01mraise[39;00m LinAlgError([38;5;124m"[39m[38;5;124mSingular matrix[39m[38;5;124m"[39m)

[1;31mLinAlgError[0m: Singular matrix
LinAlgError: Singular matrix

